ERROR 2025-05-20 22:19:04,354 log Internal Server Error: /clientAdmin/chatbot/
Traceback (most recent call last):
  File "D:\Python310\lib\site-packages\django\template\base.py", line 502, in parse
    compile_func = self.tags[command]
KeyError: 'static'

During handling of the above exception, another exception occurred:

Traceback (most recent call last):
  File "D:\Python310\lib\site-packages\asgiref\sync.py", line 518, in thread_handler
    raise exc_info[1]
  File "D:\Python310\lib\site-packages\django\core\handlers\exception.py", line 42, in inner
    response = await get_response(request)
  File "D:\Python310\lib\site-packages\django\core\handlers\base.py", line 253, in _get_response_async
    response = await wrapped_callback(
  File "D:\Python310\lib\site-packages\asgiref\sync.py", line 468, in __call__
    ret = await asyncio.shield(exec_coro)
  File "D:\Python310\lib\concurrent\futures\thread.py", line 58, in run
    result = self.fn(*self.args, **self.kwargs)
  File "D:\Python310\lib\site-packages\asgiref\sync.py", line 522, in thread_handler
    return func(*args, **kwargs)
  File "E:\.pawan\APPLICATION\github\github_fns\apps\chatbot\views.py", line 15, in chatbot
    return render(request,'admin/chatbot.html')
  File "D:\Python310\lib\site-packages\django\shortcuts.py", line 25, in render
    content = loader.render_to_string(template_name, context, request, using=using)
  File "D:\Python310\lib\site-packages\django\template\loader.py", line 61, in render_to_string
    template = get_template(template_name, using=using)
  File "D:\Python310\lib\site-packages\django\template\loader.py", line 15, in get_template
    return engine.get_template(template_name)
  File "D:\Python310\lib\site-packages\django\template\backends\django.py", line 33, in get_template
    return Template(self.engine.get_template(template_name), self)
  File "D:\Python310\lib\site-packages\django\template\engine.py", line 177, in get_template
    template, origin = self.find_template(template_name)
  File "D:\Python310\lib\site-packages\django\template\engine.py", line 159, in find_template
    template = loader.get_template(name, skip=skip)
  File "D:\Python310\lib\site-packages\django\template\loaders\cached.py", line 57, in get_template
    template = super().get_template(template_name, skip)
  File "D:\Python310\lib\site-packages\django\template\loaders\base.py", line 28, in get_template
    return Template(
  File "D:\Python310\lib\site-packages\django\template\base.py", line 154, in __init__
    self.nodelist = self.compile_nodelist()
  File "D:\Python310\lib\site-packages\django\template\base.py", line 196, in compile_nodelist
    return parser.parse()
  File "D:\Python310\lib\site-packages\django\template\base.py", line 504, in parse
    self.invalid_block_tag(token, command, parse_until)
  File "D:\Python310\lib\site-packages\django\template\base.py", line 565, in invalid_block_tag
    raise self.error(
django.template.exceptions.TemplateSyntaxError: Invalid block tag on line 164: 'static'. Did you forget to register or load this tag?
ERROR 2025-05-20 22:19:04,360 runserver HTTP GET /clientAdmin/chatbot/ 500 [0.25, 127.0.0.1:50675]
ERROR 2025-05-20 22:20:37,443 log Internal Server Error: /clientAdmin/chatbot/
Traceback (most recent call last):
  File "D:\Python310\lib\site-packages\django\template\base.py", line 502, in parse
    compile_func = self.tags[command]
KeyError: 'static'

During handling of the above exception, another exception occurred:

Traceback (most recent call last):
  File "D:\Python310\lib\site-packages\asgiref\sync.py", line 518, in thread_handler
    raise exc_info[1]
  File "D:\Python310\lib\site-packages\django\core\handlers\exception.py", line 42, in inner
    response = await get_response(request)
  File "D:\Python310\lib\site-packages\django\core\handlers\base.py", line 253, in _get_response_async
    response = await wrapped_callback(
  File "D:\Python310\lib\site-packages\asgiref\sync.py", line 468, in __call__
    ret = await asyncio.shield(exec_coro)
  File "D:\Python310\lib\concurrent\futures\thread.py", line 58, in run
    result = self.fn(*self.args, **self.kwargs)
  File "D:\Python310\lib\site-packages\asgiref\sync.py", line 522, in thread_handler
    return func(*args, **kwargs)
  File "E:\.pawan\APPLICATION\github\github_fns\apps\chatbot\views.py", line 15, in chatbot
    return render(request,'admin/chatbot.html')
  File "D:\Python310\lib\site-packages\django\shortcuts.py", line 25, in render
    content = loader.render_to_string(template_name, context, request, using=using)
  File "D:\Python310\lib\site-packages\django\template\loader.py", line 61, in render_to_string
    template = get_template(template_name, using=using)
  File "D:\Python310\lib\site-packages\django\template\loader.py", line 15, in get_template
    return engine.get_template(template_name)
  File "D:\Python310\lib\site-packages\django\template\backends\django.py", line 33, in get_template
    return Template(self.engine.get_template(template_name), self)
  File "D:\Python310\lib\site-packages\django\template\engine.py", line 177, in get_template
    template, origin = self.find_template(template_name)
  File "D:\Python310\lib\site-packages\django\template\engine.py", line 159, in find_template
    template = loader.get_template(name, skip=skip)
  File "D:\Python310\lib\site-packages\django\template\loaders\cached.py", line 57, in get_template
    template = super().get_template(template_name, skip)
  File "D:\Python310\lib\site-packages\django\template\loaders\base.py", line 28, in get_template
    return Template(
  File "D:\Python310\lib\site-packages\django\template\base.py", line 154, in __init__
    self.nodelist = self.compile_nodelist()
  File "D:\Python310\lib\site-packages\django\template\base.py", line 196, in compile_nodelist
    return parser.parse()
  File "D:\Python310\lib\site-packages\django\template\base.py", line 504, in parse
    self.invalid_block_tag(token, command, parse_until)
  File "D:\Python310\lib\site-packages\django\template\base.py", line 565, in invalid_block_tag
    raise self.error(
django.template.exceptions.TemplateSyntaxError: Invalid block tag on line 164: 'static'. Did you forget to register or load this tag?
ERROR 2025-05-20 22:20:37,449 runserver HTTP GET /clientAdmin/chatbot/ 500 [0.07, 127.0.0.1:50723]
ERROR 2025-05-20 22:20:38,624 log Internal Server Error: /clientAdmin/chatbot/
Traceback (most recent call last):
  File "D:\Python310\lib\site-packages\django\template\base.py", line 502, in parse
    compile_func = self.tags[command]
KeyError: 'static'

During handling of the above exception, another exception occurred:

Traceback (most recent call last):
  File "D:\Python310\lib\site-packages\asgiref\sync.py", line 518, in thread_handler
    raise exc_info[1]
  File "D:\Python310\lib\site-packages\django\core\handlers\exception.py", line 42, in inner
    response = await get_response(request)
  File "D:\Python310\lib\site-packages\django\core\handlers\base.py", line 253, in _get_response_async
    response = await wrapped_callback(
  File "D:\Python310\lib\site-packages\asgiref\sync.py", line 468, in __call__
    ret = await asyncio.shield(exec_coro)
  File "D:\Python310\lib\concurrent\futures\thread.py", line 58, in run
    result = self.fn(*self.args, **self.kwargs)
  File "D:\Python310\lib\site-packages\asgiref\sync.py", line 522, in thread_handler
    return func(*args, **kwargs)
  File "E:\.pawan\APPLICATION\github\github_fns\apps\chatbot\views.py", line 15, in chatbot
    return render(request,'admin/chatbot.html')
  File "D:\Python310\lib\site-packages\django\shortcuts.py", line 25, in render
    content = loader.render_to_string(template_name, context, request, using=using)
  File "D:\Python310\lib\site-packages\django\template\loader.py", line 61, in render_to_string
    template = get_template(template_name, using=using)
  File "D:\Python310\lib\site-packages\django\template\loader.py", line 15, in get_template
    return engine.get_template(template_name)
  File "D:\Python310\lib\site-packages\django\template\backends\django.py", line 33, in get_template
    return Template(self.engine.get_template(template_name), self)
  File "D:\Python310\lib\site-packages\django\template\engine.py", line 177, in get_template
    template, origin = self.find_template(template_name)
  File "D:\Python310\lib\site-packages\django\template\engine.py", line 159, in find_template
    template = loader.get_template(name, skip=skip)
  File "D:\Python310\lib\site-packages\django\template\loaders\cached.py", line 57, in get_template
    template = super().get_template(template_name, skip)
  File "D:\Python310\lib\site-packages\django\template\loaders\base.py", line 28, in get_template
    return Template(
  File "D:\Python310\lib\site-packages\django\template\base.py", line 154, in __init__
    self.nodelist = self.compile_nodelist()
  File "D:\Python310\lib\site-packages\django\template\base.py", line 196, in compile_nodelist
    return parser.parse()
  File "D:\Python310\lib\site-packages\django\template\base.py", line 504, in parse
    self.invalid_block_tag(token, command, parse_until)
  File "D:\Python310\lib\site-packages\django\template\base.py", line 565, in invalid_block_tag
    raise self.error(
django.template.exceptions.TemplateSyntaxError: Invalid block tag on line 164: 'static'. Did you forget to register or load this tag?
ERROR 2025-05-20 22:20:38,628 runserver HTTP GET /clientAdmin/chatbot/ 500 [0.05, 127.0.0.1:50723]
ERROR 2025-05-20 22:47:00,522 services Unexpected error: 'dict' object has no attribute 'data'
Traceback (most recent call last):
  File "E:\.pawan\APPLICATION\github\github_fns\apps\chatbot\services.py", line 21, in chat_bot
    payload = request.data
AttributeError: 'dict' object has no attribute 'data'
ERROR 2025-05-20 22:47:00,525 log Internal Server Error: /api/v1/chatbot/chat/
ERROR 2025-05-20 22:47:00,525 runserver HTTP POST /api/v1/chatbot/chat/ 500 [0.01, 127.0.0.1:51712]
ERROR 2025-05-20 22:51:56,474 services Unexpected error: Dify API error: {"code": "unauthorized", "message": "Access token is invalid", "status": 401}
Traceback (most recent call last):
  File "E:\.pawan\APPLICATION\github\github_fns\apps\chatbot\services.py", line 43, in chat_bot
    raise Exception(f"Dify API error: {response.text}")
Exception: Dify API error: {"code": "unauthorized", "message": "Access token is invalid", "status": 401}

ERROR 2025-05-20 22:51:56,484 log Internal Server Error: /api/v1/chatbot/chat/
ERROR 2025-05-20 22:51:56,486 runserver HTTP POST /api/v1/chatbot/chat/ 500 [3.13, 127.0.0.1:51908]
ERROR 2025-05-20 22:53:22,303 services Unexpected error: Dify API error: {"code": "invalid_param", "message": "Arg user must be provided.", "status": 400}
Traceback (most recent call last):
  File "E:\.pawan\APPLICATION\github\github_fns\apps\chatbot\services.py", line 45, in chat_bot
    raise Exception(f"Dify API error: {response.text}")
Exception: Dify API error: {"code": "invalid_param", "message": "Arg user must be provided.", "status": 400}

ERROR 2025-05-20 22:53:22,308 log Internal Server Error: /api/v1/chatbot/chat/
ERROR 2025-05-20 22:53:22,308 runserver HTTP POST /api/v1/chatbot/chat/ 500 [30.94, 127.0.0.1:51972]
ERROR 2025-05-20 22:54:56,478 services Unexpected error: Dify API error: {"code": "invalid_param", "message": "Arg user must be provided.", "status": 400}
Traceback (most recent call last):
  File "E:\.pawan\APPLICATION\github\github_fns\apps\chatbot\services.py", line 48, in chat_bot
    raise Exception(f"Dify API error: {response.text}")
Exception: Dify API error: {"code": "invalid_param", "message": "Arg user must be provided.", "status": 400}

ERROR 2025-05-20 22:54:56,482 log Internal Server Error: /api/v1/chatbot/chat/
ERROR 2025-05-20 22:54:56,482 runserver HTTP POST /api/v1/chatbot/chat/ 500 [25.21, 127.0.0.1:52046]
ERROR 2025-05-20 22:57:10,448 log Internal Server Error: /api/v1/chatbot/chat/
Traceback (most recent call last):
  File "D:\Python310\lib\site-packages\asgiref\sync.py", line 518, in thread_handler
    raise exc_info[1]
  File "D:\Python310\lib\site-packages\django\core\handlers\exception.py", line 42, in inner
    response = await get_response(request)
  File "D:\Python310\lib\site-packages\django\core\handlers\base.py", line 284, in _get_response_async
    response = await sync_to_async(
  File "D:\Python310\lib\site-packages\asgiref\sync.py", line 468, in __call__
    ret = await asyncio.shield(exec_coro)
  File "D:\Python310\lib\concurrent\futures\thread.py", line 58, in run
    result = self.fn(*self.args, **self.kwargs)
  File "D:\Python310\lib\site-packages\asgiref\sync.py", line 522, in thread_handler
    return func(*args, **kwargs)
  File "D:\Python310\lib\site-packages\django\template\response.py", line 114, in render
    self.content = self.rendered_content
  File "D:\Python310\lib\site-packages\rest_framework\response.py", line 74, in rendered_content
    ret = renderer.render(self.data, accepted_media_type, context)
  File "D:\Python310\lib\site-packages\rest_framework\renderers.py", line 99, in render
    ret = json.dumps(
  File "D:\Python310\lib\site-packages\rest_framework\utils\json.py", line 25, in dumps
    return json.dumps(*args, **kwargs)
  File "D:\Python310\lib\json\__init__.py", line 238, in dumps
    **kw).encode(obj)
  File "D:\Python310\lib\json\encoder.py", line 199, in encode
    chunks = self.iterencode(o, _one_shot=True)
  File "D:\Python310\lib\json\encoder.py", line 257, in iterencode
    return _iterencode(o, 0)
  File "D:\Python310\lib\site-packages\rest_framework\utils\encoders.py", line 67, in default
    return super().default(obj)
  File "D:\Python310\lib\json\encoder.py", line 179, in default
    raise TypeError(f'Object of type {o.__class__.__name__} '
TypeError: Object of type ResStatus is not JSON serializable
ERROR 2025-05-20 22:57:10,454 runserver HTTP POST /api/v1/chatbot/chat/ 500 [24.92, 127.0.0.1:52174]
ERROR 2025-05-20 23:00:06,446 services Unexpected error: 
Traceback (most recent call last):
  File "E:\.pawan\APPLICATION\github\github_fns\apps\chatbot\services.py", line 47, in chat_bot
    if response.status_code != 200:
  File "E:\.pawan\APPLICATION\github\github_fns\apps\chatbot\services.py", line 47, in chat_bot
    if response.status_code != 200:
  File "D:\Python310\lib\bdb.py", line 90, in trace_dispatch
    return self.dispatch_line(frame)
  File "D:\Python310\lib\bdb.py", line 115, in dispatch_line
    if self.quitting: raise BdbQuit
bdb.BdbQuit
ERROR 2025-05-20 23:42:01,001 services Groq chatbot error: Groq API error: {"error":{"message":"The model `llama-3-70b-8192` does not exist or you do not have access to it.","type":"invalid_request_error","code":"model_not_found"}}
Traceback (most recent call last):
  File "E:\.pawan\APPLICATION\github\github_fns\apps\chatbot\services.py", line 111, in chat_bot_grok
    raise Exception(f"Groq API error: {response.text}")
Exception: Groq API error: {"error":{"message":"The model `llama-3-70b-8192` does not exist or you do not have access to it.","type":"invalid_request_error","code":"model_not_found"}}

ERROR 2025-05-20 23:42:01,005 log Internal Server Error: /api/v1/chatbot/chat/
ERROR 2025-05-20 23:42:01,005 runserver HTTP POST /api/v1/chatbot/chat/ 500 [57.10, 127.0.0.1:53996]
ERROR 2025-05-20 23:45:19,000 services Groq chatbot error: Groq API error: {"error":{"message":"The model `llama-3-70b-8192` does not exist or you do not have access to it.","type":"invalid_request_error","code":"model_not_found"}}
Traceback (most recent call last):
  File "E:\.pawan\APPLICATION\github\github_fns\apps\chatbot\services.py", line 111, in chat_bot_grok
    raise Exception(f"Groq API error: {response.text}")
Exception: Groq API error: {"error":{"message":"The model `llama-3-70b-8192` does not exist or you do not have access to it.","type":"invalid_request_error","code":"model_not_found"}}

ERROR 2025-05-20 23:45:19,004 log Internal Server Error: /api/v1/chatbot/chat/
ERROR 2025-05-20 23:45:19,004 runserver HTTP POST /api/v1/chatbot/chat/ 500 [107.69, 127.0.0.1:54102]
